Run python backup_to_drive.py
Traceback (most recent call last):
  File "/home/runner/work/MEMEPEDIA-CONTENT/MEMEPEDIA-CONTENT/backup_to_drive.py", line 21, in <module>
    results = drive_service.files().list(pageSize=5).execute()
  File "/opt/hostedtoolcache/Python/3.13.3/x64/lib/python3.13/site-packages/googleapiclient/_helpers.py", line 130, in positional_wrapper
    return wrapped(*args, **kwargs)
  File "/opt/hostedtoolcache/Python/3.13.3/x64/lib/python3.13/site-packages/googleapiclient/http.py", line 923, in execute
    resp, content = _retry_request(
                    ~~~~~~~~~~~~~~^
        http,
        ^^^^^
    ...<7 lines>...
        headers=self.headers,
        ^^^^^^^^^^^^^^^^^^^^^
    )
    ^
  File "/opt/hostedtoolcache/Python/3.13.3/x64/lib/python3.13/site-packages/googleapiclient/http.py", line 191, in _retry_request
    resp, content = http.request(uri, method, *args, **kwargs)
                    ~~~~~~~~~~~~^^^^^^^^^^^^^^^^^^^^^^^^^^^^^^
  File "/opt/hostedtoolcache/Python/3.13.3/x64/lib/python3.13/site-packages/google_auth_httplib2.py", line 209, in request
    self.credentials.before_request(self._request, method, uri, request_headers)
    ~~~~~~~~~~~~~~~~~~~~~~~~~~~~~~~^^^^^^^^^^^^^^^^^^^^^^^^^^^^^^^^^^^^^^^^^^^^^
  File "/opt/hostedtoolcache/Python/3.13.3/x64/lib/python3.13/site-packages/google/auth/credentials.py", line 239, in before_request
    self._blocking_refresh(request)
    ~~~~~~~~~~~~~~~~~~~~~~^^^^^^^^^
  File "/opt/hostedtoolcache/Python/3.13.3/x64/lib/python3.13/site-packages/google/auth/credentials.py", line 202, in _blocking_refresh
    self.refresh(request)
    ~~~~~~~~~~~~^^^^^^^^^
  File "/opt/hostedtoolcache/Python/3.13.3/x64/lib/python3.13/site-packages/google/oauth2/credentials.py", line 409, in refresh
    ) = reauth.refresh_grant(
        ~~~~~~~~~~~~~~~~~~~~^
        request,
        ^^^^^^^^
    ...<6 lines>...
        enable_reauth_refresh=self._enable_reauth_refresh,
        ^^^^^^^^^^^^^^^^^^^^^^^^^^^^^^^^^^^^^^^^^^^^^^^^^^
    )
    ^
  File "/opt/hostedtoolcache/Python/3.13.3/x64/lib/python3.13/site-packages/google/oauth2/reauth.py", line 366, in refresh_grant
    _client._handle_error_response(response_data, retryable_error)
    ~~~~~~~~~~~~~~~~~~~~~~~~~~~~~~^^^^^^^^^^^^^^^^^^^^^^^^^^^^^^^^
  File "/opt/hostedtoolcache/Python/3.13.3/x64/lib/python3.13/site-packages/google/oauth2/_client.py", line 69, in _handle_error_response
    raise exceptions.RefreshError(
        error_details, response_data, retryable=retryable_error
    )
google.auth.exceptions.RefreshError: ('invalid_request: Missing required parameter: refresh_token', {'error': 'invalid_request', 'error_description': 'Missing required parameter: refresh_token'})
Error: Process completed with exit code 1.